
Traceback (most recent call last):
  File "tests/exceptions/source/backtrace/chaining_second.py", line 38, in <module>
    a_decorator()
> File "tests/exceptions/source/backtrace/chaining_second.py", line 10, in a_decorator
    b_decorated()
  File "tests/exceptions/source/backtrace/chaining_second.py", line 27, in b_decorated
    c()
  File "tests/exceptions/source/backtrace/chaining_second.py", line 35, in c
    1 / 0
ZeroDivisionError: division by zero

Traceback (most recent call last):
  File "tests/exceptions/source/backtrace/chaining_second.py", line 39, in <module>
    a_context_manager()
> File "tests/exceptions/source/backtrace/chaining_second.py", line 15, in a_context_manager
    b_not_decorated()
  File "tests/exceptions/source/backtrace/chaining_second.py", line 31, in b_not_decorated
    c()
  File "tests/exceptions/source/backtrace/chaining_second.py", line 35, in c
    1 / 0
ZeroDivisionError: division by zero

Traceback (most recent call last):
  File "tests/exceptions/source/backtrace/chaining_second.py", line 40, in <module>
    a_explicit()
> File "tests/exceptions/source/backtrace/chaining_second.py", line 20, in a_explicit
    b_not_decorated()
  File "tests/exceptions/source/backtrace/chaining_second.py", line 31, in b_not_decorated
    c()
  File "tests/exceptions/source/backtrace/chaining_second.py", line 35, in c
    1 / 0
ZeroDivisionError: division by zero
